--app=Ver_2_Tests --port=1886 --group=4 --data=127.0.0.1:6379 --edge=1 --long=57.3692 --lat=76.4314 --localregistryhost=0 --device

------

Current Device Node Id: e5e05664-f45b-4f45-b65d-9765da01f6d6

Starting App..

Program completed.

hello.. main loop.. calling the C function testfunc..  

hello.. main loop.. calling the C function testfunc..  

STDERR: 
node:internal/event_target:1012
  process.nextTick(() => { throw err; });
                           ^
STDERR: UnhandledPromiseRejection: This error originated either by throwing inside of an async function without a catch block, or by rejecting a promise which was not handled with .catch(). The promise rejected with the reason "network error".
Emitted 'error' event on Worker instance at:
    at [kOnErrorMessage] (node:internal/worker:300:10)
    at [kOnMessage] (node:internal/worker:311:37)
    at MessagePort.<anonymous> (node:internal/worker:212:57)
    at [nodejs.internal.kHybridDispatch] (node:internal/event_target:737:20)
    at exports.emitMessage (node:internal/per_context/messageport:23:28) {
  code: 'ERR_UNHANDLED_REJECTION'
}

Node.js v18.16.0
Killing broker with PID: 110186




Test: jt4 Completed Succesfully
Time to Compile: 13.456s
Time to Run Test: 10.009s
