--app=Ver_2_Tests --port=1884 --group=2 --data=127.0.0.1:6379 --edge=1 --long=112.1032 --lat=23.3006 --localregistryhost=0 --device
------
Current Device Node Id: c8358bea-5e74-45e7-84fe-744fd41579e0
Starting App..
Program completed.
hello.. main loop.. calling the C function testfunc..  
hello.. main loop.. calling the C function testfunc..  
hello.. main loop.. calling the C function testfunc..  
hello.. main loop.. calling the C function testfunc..  
hello.. main loop.. calling the C function testfunc..  
Killing broker with PID:

STDERR: 
node:internal/event_target:1037
  process.nextTick(() => { throw err; });
                           ^
UnhandledPromiseRejection: This error originated either by throwing inside of an async function without a catch block, or by rejecting a promise which was not handled with .catch(). The promise rejected with the reason "timeout error".
Emitted 'error' event on Worker instance at:
    at [kOnErrorMessage] (node:internal/worker:323:10)
    at [kOnMessage] (node:internal/worker:334:37)
    at MessagePort.<anonymous> (node:internal/worker:229:57)
    at [nodejs.internal.kHybridDispatch] (node:internal/event_target:762:20)
    at exports.emitMessage (node:internal/per_context/messageport:23:28) {
  code: 'ERR_UNHANDLED_REJECTION'
}

Node.js v20.2.0
kill: usage: kill [-s sigspec | -n signum | -sigspec] pid | jobspec ... or kill -l [sigspec]



Test: jt4 Completed Succesfully
Time to Compile: 1.505s
Time to Run Test: 10.002s
